Workbook

Sheet Accueil
A1: Pilotage locatif
A2: Outil de suivi d'un ou plusieurs biens en location. Version 1.2, 26/10/2026.
A5: Comment l'utiliser
A6: 1. Biens | B6: Renseignez une ligne par bien (identifiant, régime fiscal, coût d'acquisition, date de mise en location).
A7: 2. Journal | B7: Saisissez chaque mouvement : relevé de l'agence (montants bruts : loyers, honoraires, travaux) et dépenses payées depuis la banque. Le prêt ne se saisit pas ici.
A8: 3. Prêts et Échéancier | B8: Une ligne par prêt, et le tableau d'amortissement de la banque collé dans l'Échéancier.
A9: 4. Amortissements | B9: Le plan d'amortissement du comptable, et chaque nouvel équipement immobilisé.
A10: 5. Synthèse | B10: Choisissez le bien en C3 : résultat fiscal estimé, cash-flow et rentabilité par année.
A11: 6. Revente et Vendre quand | B11: Revente : détail de la somme perçue et de la plus-value pour une date. Vendre quand : comparaison de trois dates de vente (somme nette, impôt, effort de trésorerie, gain total et TRI depuis l'achat).
A12: 7. Contrôles | B12: Vérifiez que tout est « OK » ou « Écart expliqué ».
A14: Code couleur
A15: Fond jaune, texte bleu | B15: Cellule à saisir
A16: Fond gris | B16: Calcul automatique : ne pas modifier
A17: Texte noir | B17: Formule
A19: Ce qui change par rapport au fichier d'origine
A20: Un seul journal | B20: Les deux listings (dépenses, recettes) fusionnent en une table, avec bien, compte, catégorie, pièce justificative.
A21: Référentiels | B21: Biens, catégories (avec traitement fiscal LMNP) et listes déroulantes : plus de codes tapés à la main, plus de montants qui disparaissent des totaux.
A22: Multi-biens | B22: Chaque ligne est rattachée à un bien ; la synthèse se filtre par bien.
A23: Prêt | B23: Un seul échéancier pour tous les prêts (au lieu d'un onglet par prêt aux mises en page différentes) ; il fait foi pour le capital, les intérêts et l'assurance.
A24: Fiscalité LMNP réel | B24: Nouvel onglet Amortissements et calcul du résultat fiscal avec report des amortissements, absents du fichier d'origine.
A25: Synthèse | B25: Recap et Ratio Trésorerie remplacés par une synthèse unique : résultat fiscal, cash-flow, rendements, capital restant dû.
A26: Revente | B26: Simulation corrigée : capital restant dû exact, somme nette, cash-flow cumulé, amortissements à réintégrer.
A27: Nouveaux onglets | B27: Échéances (rappels annuels) et Contrôles (rapprochement avec l'agence et les comptes du comptable).
A28: Erreurs corrigées | B28: Addition capital restant dû + mensualité, intérêts décalés d'un mois, capital du prêt 1 jamais compté, formules limitées à 93 lignes, cumul fiscal faux, valeurs en dur.
A30: Données de départ
A31: Contenu | B31: Mise en location du 18/05/2024 au 25/10/2026 : grand livre de l'agence (ligne à ligne), dépenses payées depuis le compte BANQUE, assurance PNO d'après les comptes annuels, échéancier BANQUE complet, plan d'amortissement déduit des comptes 2024 et 2025.
A32: Avertissement | B32: Outil de suivi, pas un conseil fiscal. Les règles fiscales sont à confirmer avec un expert-comptable ou sur impots.gouv.fr.
A34: Nouveautés de la version 1.2
A35: Vendre quand | B35: Nouvel onglet : trois dates de vente comparées (somme nette, impôt sur la plus-value, exonération pour remploi, cash-flow d'ici la vente, gain total et TRI depuis l'achat, rendement de l'attente).
A36: Avant la location | B36: Les dépenses payées pendant l'occupation et la vacance (copropriété, taxe foncière) se saisissent dans l'onglet Vendre quand, sans fausser le résultat fiscal.
A37: Contrôles | B37: Nouveau contrôle : l'onglet Vendre quand retombe sur l'onglet Revente pour une même date et un même prix.

Sheet Synthèse
A1: Synthèse annuelle
A2: Tout est calculé à partir du Journal, de l'Échéancier et des Amortissements. Choisissez le bien en C3.
B3: Bien | C3: APPART-01 | E3: =IFERROR(INDEX(Biens!$B$5:$B$30,MATCH(Synthèse!$C$3,Biens!$A$5:$A$30,0)),0) -> Appartement exemple
B4: Données à jour au | C4: 46320 | E4: ="Régime : "&IFERROR(INDEX(Biens!$G$5:$G$30,MATCH(Synthèse!$C$3,Biens!$A$5:$A$30,0)),0) -> Régime : LMNP réel | G4: Mis en location le | H4: =IFERROR(INDEX(Biens!$O$5:$O$30,MATCH(Synthèse!$C$3,Biens!$A$5:$A$30,0)),0) -> 45430
B7: Rubrique | D7: 2024 | E7: 2025 | F7: 2026 | G7: 2027 | H7: 2028
B9: 1. Résultat fiscal estimé (LMNP réel)
B10: Loyers hors charges | D10: =IF(D$7>YEAR($C$4),"",SUMIFS(Journal!$K$5:$K$1004,Journal!$C$5:$C$1004,$C$3,Journal!$B$5:$B$1004,D$7,Journal!$E$5:$E$1004,"Loyer hors charges")) -> 7692.3 | E10: =IF(E$7>YEAR($C$4),"",SUMIFS(Journal!$K$5:$K$1004,Journal!$C$5:$C$1004,$C$3,Journal!$B$5:$B$1004,E$7,Journal!$E$5:$E$1004,"Loyer hors charges")) -> 12387.89 | F10: =IF(F$7>YEAR($C$4),"",SUMIFS(Journal!$K$5:$K$1004,Journal!$C$5:$C$1004,$C$3,Journal!$B$5:$B$1004,F$7,Journal!$E$5:$E$1004,"Loyer hors charges")) -> 10511.92 | G10: =IF(G$7>YEAR($C$4),"",SUMIFS(Journal!$K$5:$K$1004,Journal!$C$5:$C$1004,$C$3,Journal!$B$5:$B$1004,G$7,Journal!$E$5:$E$1004,"Loyer hors charges")) | H10: =IF(H$7>YEAR($C$4),"",SUMIFS(Journal!$K$5:$K$1004,Journal!$C$5:$C$1004,$C$3,Journal!$B$5:$B$1004,H$7,Journal!$E$5:$E$1004,"Loyer hors charges"))
B11: Charges refacturées au locataire | D11: =IF(D$7>YEAR($C$4),"",SUMIFS(Journal!$K$5:$K$1004,Journal!$C$5:$C$1004,$C$3,Journal!$B$5:$B$1004,D$7,Journal!$J$5:$J$1004,"Charges refacturées")) -> 674.46 | E11: =IF(E$7>YEAR($C$4),"",SUMIFS(Journal!$K$5:$K$1004,Journal!$C$5:$C$1004,$C$3,Journal!$B$5:$B$1004,E$7,Journal!$J$5:$J$1004,"Charges refacturées")) -> 1315.26 | F11: =IF(F$7>YEAR($C$4),"",SUMIFS(Journal!$K$5:$K$1004,Journal!$C$5:$C$1004,$C$3,Journal!$B$5:$B$1004,F$7,Journal!$J$5:$J$1004,"Charges refacturées")) -> 920.7 | G11: =IF(G$7>YEAR($C$4),"",SUMIFS(Journal!$K$5:$K$1004,Journal!$C$5:$C$1004,$C$3,Journal!$B$5:$B$1004,G$7,Journal!$J$5:$J$1004,"Charges refacturées")) | H11: =IF(H$7>YEAR($C$4),"",SUMIFS(Journal!$K$5:$K$1004,Journal!$C$5:$C$1004,$C$3,Journal!$B$5:$B$1004,H$7,Journal!$J$5:$J$1004,"Charges refacturées"))
B12: Autres recettes | D12: =IF(D$7>YEAR($C$4),"",SUMIFS(Journal!$K$5:$K$1004,Journal!$C$5:$C$1004,$C$3,Journal!$B$5:$B$1004,D$7,Journal!$J$5:$J$1004,"Autres recettes")) -> 0 | E12: =IF(E$7>YEAR($C$4),"",SUMIFS(Journal!$K$5:$K$1004,Journal!$C$5:$C$1004,$C$3,Journal!$B$5:$B$1004,E$7,Journal!$J$5:$J$1004,"Autres recettes")) -> 0 | F12: =IF(F$7>YEAR($C$4),"",SUMIFS(Journal!$K$5:$K$1004,Journal!$C$5:$C$1004,$C$3,Journal!$B$5:$B$1004,F$7,Journal!$J$5:$J$1004,"Autres recettes")) -> 0 | G12: =IF(G$7>YEAR($C$4),"",SUMIFS(Journal!$K$5:$K$1004,Journal!$C$5:$C$1004,$C$3,Journal!$B$5:$B$1004,G$7,Journal!$J$5:$J$1004,"Autres recettes")) | H12: =IF(H$7>YEAR($C$4),"",SUMIFS(Journal!$K$5:$K$1004,Journal!$C$5:$C$1004,$C$3,Journal!$B$5:$B$1004,H$7,Journal!$J$5:$J$1004,"Autres recettes"))
B13: Total des recettes imposables | D13: =IF(D$7>YEAR($C$4),"",SUMIFS(Journal!$K$5:$K$1004,Journal!$C$5:$C$1004,$C$3,Journal!$B$5:$B$1004,D$7,Journal!$I$5:$I$1004,"Imposable")) -> 8366.76 | E13: =IF(E$7>YEAR($C$4),"",SUMIFS(Journal!$K$5:$K$1004,Journal!$C$5:$C$1004,$C$3,Journal!$B$5:$B$1004,E$7,Journal!$I$5:$I$1004,"Imposable")) -> 13703.15 | F13: =IF(F$7>YEAR($C$4),"",SUMIFS(Journal!$K$5:$K$1004,Journal!$C$5:$C$1004,$C$3,Journal!$B$5:$B$1004,F$7,Journal!$I$5:$I$1004,"Imposable")) -> 11432.62 | G13: =IF(G$7>YEAR($C$4),"",SUMIFS(Journal!$K$5:$K$1004,Journal!$C$5:$C$1004,$C$3,Journal!$B$5:$B$1004,G$7,Journal!$I$5:$I$1004,"Imposable")) | H13: =IF(H$7>YEAR($C$4),"",SUMIFS(Journal!$K$5:$K$1004,Journal!$C$5:$C$1004,$C$3,Journal!$B$5:$B$1004,H$7,Journal!$I$5:$I$1004,"Imposable"))
B15: Frais de gestion (agence, comptable) | D15: =IF(D$7>YEAR($C$4),"",-SUMIFS(Journal!$K$5:$K$1004,Journal!$C$5:$C$1004,$C$3,Journal!$B$5:$B$1004,D$7,Journal!$J$5:$J$1004,"Frais de gestion",Journal!$I$5:$I$1004,"Déductible")) -> 1260.15 | E15: =IF(E$7>YEAR($C$4),"",-SUMIFS(Journal!$K$5:$K$1004,Journal!$C$5:$C$1004,$C$3,Journal!$B$5:$B$1004,E$7,Journal!$J$5:$J$1004,"Frais de gestion",Journal!$I$5:$I$1004,"Déductible")) -> 1611.54 | F15: =IF(F$7>YEAR($C$4),"",-SUMIFS(Journal!$K$5:$K$1004,Journal!$C$5:$C$1004,$C$3,Journal!$B$5:$B$1004,F$7,Journal!$J$5:$J$1004,"Frais de gestion",Journal!$I$5:$I$1004,"Déductible")) -> 1411.05 | G15: =IF(G$7>YEAR($C$4),"",-SUMIFS(Journal!$K$5:$K$1004,Journal!$C$5:$C$1004,$C$3,Journal!$B$5:$B$1004,G$7,Journal!$J$5:$J$1004,"Frais de gestion",Journal!$I$5:$I$1004,"Déductible")) | H15: =IF(H$7>YEAR($C$4),"",-SUMIFS(Journal!$K$5:$K$1004,Journal!$C$5:$C$1004,$C$3,Journal!$B$5:$B$1004,H$7,Journal!$J$5:$J$1004,"Frais de gestion",Journal!$I$5:$I$1004,"Déductible"))
B16: Copropriété | D16: =IF(D$7>YEAR($C$4),"",-SUMIFS(Journal!$K$5:$K$1004,Journal!$C$5:$C$1004,$C$3,Journal!$B$5:$B$1004,D$7,Journal!$J$5:$J$1004,"Copropriété",Journal!$I$5:$I$1004,"Déductible")) -> 1177.59 | E16: =IF(E$7>YEAR($C$4),"",-SUMIFS(Journal!$K$5:$K$1004,Journal!$C$5:$C$1004,$C$3,Journal!$B$5:$B$1004,E$7,Journal!$J$5:$J$1004,"Copropriété",Journal!$I$5:$I$1004,"Déductible")) -> 2426.77 | F16: =IF(F$7>YEAR($C$4),"",-SUMIFS(Journal!$K$5:$K$1004,Journal!$C$5:$C$1004,$C$3,Journal!$B$5:$B$1004,F$7,Journal!$J$5:$J$1004,"Copropriété",Journal!$I$5:$I$1004,"Déductible")) -> 3791.6 | G16: =IF(G$7>YEAR($C$4),"",-SUMIFS(Journal!$K$5:$K$1004,Journal!$C$5:$C$1004,$C$3,Journal!$B$5:$B$1004,G$7,Journal!$J$5:$J$1004,"Copropriété",Journal!$I$5:$I$1004,"Déductible")) | H16: =IF(H$7>YEAR($C$4),"",-SUMIFS(Journal!$K$5:$K$1004,Journal!$C$5:$C$1004,$C$3,Journal!$B$5:$B$1004,H$7,Journal!$J$5:$J$1004,"Copropriété",Journal!$I$5:$I$1004,"Déductible"))
B17: Assurances | D17: =IF(D$7>YEAR($C$4),"",-SUMIFS(Journal!$K$5:$K$1004,Journal!$C$5:$C$1004,$C$3,Journal!$B$5:$B$1004,D$7,Journal!$J$5:$J$1004,"Assurances",Journal!$I$5:$I$1004,"Déductible")) -> 105.8 | E17: =IF(E$7>YEAR($C$4),"",-SUMIFS(Journal!$K$5:$K$1004,Journal!$C$5:$C$1004,$C$3,Journal!$B$5:$B$1004,E$7,Journal!$J$5:$J$1004,"Assurances",Journal!$I$5:$I$1004,"Déductible")) -> 114.18 | F17: =IF(F$7>YEAR($C$4),"",-SUMIFS(Journal!$K$5:$K$1004,Journal!$C$5:$C$1004,$C$3,Journal!$B$5:$B$1004,F$7,Journal!$J$5:$J$1004,"Assurances",Journal!$I$5:$I$1004,"Déductible")) -> 0 | G17: =IF(G$7>YEAR($C$4),"",-SUMIFS(Journal!$K$5:$K$1004,Journal!$C$5:$C$1004,$C$3,Journal!$B$5:$B$1004,G$7,Journal!$J$5:$J$1004,"Assurances",Journal!$I$5:$I$1004,"Déductible")) | H17: =IF(H$7>YEAR($C$4),"",-SUMIFS(Journal!$K$5:$K$1004,Journal!$C$5:$C$1004,$C$3,Journal!$B$5:$B$1004,H$7,Journal!$J$5:$J$1004,"Assurances",Journal!$I$5:$I$1004,"Déductible"))
B18: Impôts et taxes | D18: =IF(D$7>YEAR($C$4),"",-SUMIFS(Journal!$K$5:$K$1004,Journal!$C$5:$C$1004,$C$3,Journal!$B$5:$B$1004,D$7,Journal!$J$5:$J$1004,"Impôts et taxes",Journal!$I$5:$I$1004,"Déductible")) -> 553.35 | E18: =IF(E$7>YEAR($C$4),"",-SUMIFS(Journal!$K$5:$K$1004,Journal!$C$5:$C$1004,$C$3,Journal!$B$5:$B$1004,E$7,Journal!$J$5:$J$1004,"Impôts et taxes",Journal!$I$5:$I$1004,"Déductible")) -> 561.72 | F18: =IF(F$7>YEAR($C$4),"",-SUMIFS(Journal!$K$5:$K$1004,Journal!$C$5:$C$1004,$C$3,Journal!$B$5:$B$1004,F$7,Journal!$J$5:$J$1004,"Impôts et taxes",Journal!$I$5:$I$1004,"Déductible")) -> 885.36 | G18: =IF(G$7>YEAR($C$4),"",-SUMIFS(Journal!$K$5:$K$1004,Journal!$C$5:$C$1004,$C$3,Journal!$B$5:$B$1004,G$7,Journal!$J$5:$J$1004,"Impôts et taxes",Journal!$I$5:$I$1004,"Déductible")) | H18: =IF(H$7>YEAR($C$4),"",-SUMIFS(Journal!$K$5:$K$1004,Journal!$C$5:$C$1004,$C$3,Journal!$B$5:$B$1004,H$7,Journal!$J$5:$J$1004,"Impôts et taxes",Journal!$I$5:$I$1004,"Déductible"))
B19: Entretien et petit équipement | D19: =IF(D$7>YEAR($C$4),"",-SUMIFS(Journal!$K$5:$K$1004,Journal!$C$5:$C$1004,$C$3,Journal!$B$5:$B$1004,D$7,Journal!$J$5:$J$1004,"Entretien et petit équipement",Journal!$I$5:$I$1004,"Déductible")) -> 453.84 | E19: =IF(E$7>YEAR($C$4),"",-SUMIFS(Journal!$K$5:$K$1004,Journal!$C$5:$C$1004,$C$3,Journal!$B$5:$B$1004,E$7,Journal!$J$5:$J$1004,"Entretien et petit équipement",Journal!$I$5:$I$1004,"Déductible")) -> 386.42 | F19: =IF(F$7>YEAR($C$4),"",-SUMIFS(Journal!$K$5:$K$1004,Journal!$C$5:$C$1004,$C$3,Journal!$B$5:$B$1004,F$7,Journal!$J$5:$J$1004,"Entretien et petit équipement",Journal!$I$5:$I$1004,"Déductible")) -> 1141.67 | G19: =IF(G$7>YEAR($C$4),"",-SUMIFS(Journal!$K$5:$K$1004,Journal!$C$5:$C$1004,$C$3,Journal!$B$5:$B$1004,G$7,Journal!$J$5:$J$1004,"Entretien et petit équipement",Journal!$I$5:$I$1004,"Déductible")) | H19: =IF(H$7>YEAR($C$4),"",-SUMIFS(Journal!$K$5:$K$1004,Journal!$C$5:$C$1004,$C$3,Journal!$B$5:$B$1004,H$7,Journal!$J$5:$J$1004,"Entretien et petit équipement",Journal!$I$5:$I$1004,"Déductible"))
B20: Autres charges | D20: =IF(D$7>YEAR($C$4),"",-SUMIFS(Journal!$K$5:$K$1004,Journal!$C$5:$C$1004,$C$3,Journal!$B$5:$B$1004,D$7,Journal!$J$5:$J$1004,"Autres charges",Journal!$I$5:$I$1004,"Déductible")) -> 0 | E20: =IF(E$7>YEAR($C$4),"",-SUMIFS(Journal!$K$5:$K$1004,Journal!$C$5:$C$1004,$C$3,Journal!$B$5:$B$1004,E$7,Journal!$J$5:$J$1004,"Autres charges",Journal!$I$5:$I$1004,"Déductible")) -> 0 | F20: =IF(F$7>YEAR($C$4),"",-SUMIFS(Journal!$K$5:$K$1004,Journal!$C$5:$C$1004,$C$3,Journal!$B$5:$B$1004,F$7,Journal!$J$5:$J$1004,"Autres charges",Journal!$I$5:$I$1004,"Déductible")) -> 0 | G20: =IF(G$7>YEAR($C$4),"",-SUMIFS(Journal!$K$5:$K$1004,Journal!$C$5:$C$1004,$C$3,Journal!$B$5:$B$1004,G$7,Journal!$J$5:$J$1004,"Autres charges",Journal!$I$5:$I$1004,"Déductible")) | H20: =IF(H$7>YEAR($C$4),"",-SUMIFS(Journal!$K$5:$K$1004,Journal!$C$5:$C$1004,$C$3,Journal!$B$5:$B$1004,H$7,Journal!$J$5:$J$1004,"Autres charges",Journal!$I$5:$I$1004,"Déductible"))
B21: Intérêts d'emprunt (période louée) | D21: =IF(D$7>YEAR($C$4),"",SUMIFS(Échéancier!$G$5:$G$300,Échéancier!$J$5:$J$300,$C$3,Échéancier!$D$5:$D$300,D$7,Échéancier!$K$5:$K$300,1,Échéancier!$C$5:$C$300,"<="&$C$4)) -> 1035.57 | E21: =IF(E$7>YEAR($C$4),"",SUMIFS(Échéancier!$G$5:$G$300,Échéancier!$J$5:$J$300,$C$3,Échéancier!$D$5:$D$300,E$7,Échéancier!$K$5:$K$300,1,Échéancier!$C$5:$C$300,"<="&$C$4)) -> 1678.76 | F21: =IF(F$7>YEAR($C$4),"",SUMIFS(Échéancier!$G$5:$G$300,Échéancier!$J$5:$J$300,$C$3,Échéancier!$D$5:$D$300,F$7,Échéancier!$K$5:$K$300,1,Échéancier!$C$5:$C$300,"<="&$C$4)) -> 1304.71 | G21: =IF(G$7>YEAR($C$4),"",SUMIFS(Échéancier!$G$5:$G$300,Échéancier!$J$5:$J$300,$C$3,Échéancier!$D$5:$D$300,G$7,Échéancier!$K$5:$K$300,1,Échéancier!$C$5:$C$300,"<="&$C$4)) | H21: =IF(H$7>YEAR($C$4),"",SUMIFS(Échéancier!$G$5:$G$300,Échéancier!$J$5:$J$300,$C$3,Échéancier!$D$5:$D$300,H$7,Échéancier!$K$5:$K$300,1,Échéancier!$C$5:$C$300,"<="&$C$4))
B22: Assurance emprunteur (période louée) | D22: =IF(D$7>YEAR($C$4),"",SUMIFS(Échéancier!$H$5:$H$300,Échéancier!$J$5:$J$300,$C$3,Échéancier!$D$5:$D$300,D$7,Échéancier!$K$5:$K$300,1,Échéancier!$C$5:$C$300,"<="&$C$4)) -> 140.56 | E22: =IF(E$7>YEAR($C$4),"",SUMIFS(Échéancier!$H$5:$H$300,Échéancier!$J$5:$J$300,$C$3,Échéancier!$D$5:$D$300,E$7,Échéancier!$K$5:$K$300,1,Échéancier!$C$5:$C$300,"<="&$C$4)) -> 240.96 | F22: =IF(F$7>YEAR($C$4),"",SUMIFS(Échéancier!$H$5:$H$300,Échéancier!$J$5:$J$300,$C$3,Échéancier!$D$5:$D$300,F$7,Échéancier!$K$5:$K$300,1,Échéancier!$C$5:$C$300,"<="&$C$4)) -> 200.8 | G22: =IF(G$7>YEAR($C$4),"",SUMIFS(Échéancier!$H$5:$H$300,Échéancier!$J$5:$J$300,$C$3,Échéancier!$D$5:$D$300,G$7,Échéancier!$K$5:$K$300,1,Échéancier!$C$5:$C$300,"<="&$C$4)) | H22: =IF(H$7>YEAR($C$4),"",SUMIFS(Échéancier!$H$5:$H$300,Échéancier!$J$5:$J$300,$C$3,Échéancier!$D$5:$D$300,H$7,Échéancier!$K$5:$K$300,1,Échéancier!$C$5:$C$300,"<="&$C$4))
B23: Total des charges déductibles | D23: =IF(D$7>YEAR($C$4),"",SUM(D15:D22)) -> 4726.86 | E23: =IF(E$7>YEAR($C$4),"",SUM(E15:E22)) -> 7020.35 | F23: =IF(F$7>YEAR($C$4),"",SUM(F15:F22)) -> 8735.19 | G23: =IF(G$7>YEAR($C$4),"",SUM(G15:G22)) | H23: =IF(H$7>YEAR($C$4),"",SUM(H15:H22))
B24: Résultat avant amortissements | D24: =IF(D$7>YEAR($C$4),"",D13-D23) -> 3639.9 | E24: =IF(E$7>YEAR($C$4),"",E13-E23) -> 6682.8 | F24: =IF(F$7>YEAR($C$4),"",F13-F23) -> 2697.43 | G24: =IF(G$7>YEAR($C$4),"",G13-G23) | H24: =IF(H$7>YEAR($C$4),"",H13-H23)
B25: Dotations aux amortissements de l'année | D25: =IF(D$7>YEAR($C$4),"",SUMPRODUCT((Amortissements!$A$5:$A$40=$C$3)*(Amortissements!$H$4:$L$4=D$7)*Amortissements!$H$5:$L$40)) -> 5751.0489 | E25: =IF(E$7>YEAR($C$4),"",SUMPRODUCT((Amortissements!$A$5:$A$40=$C$3)*(Amortissements!$H$4:$L$4=E$7)*Amortissements!$H$5:$L$40)) -> 9297.3367 | F25: =IF(F$7>YEAR($C$4),"",SUMPRODUCT((Amortissements!$A$5:$A$40=$C$3)*(Amortissements!$H$4:$L$4=F$7)*Amortissements!$H$5:$L$40)) -> 9388.3868 | G25: =IF(G$7>YEAR($C$4),"",SUMPRODUCT((Amortissements!$A$5:$A$40=$C$3)*(Amortissements!$H$4:$L$4=G$7)*Amortissements!$H$5:$L$40)) | H25: =IF(H$7>YEAR($C$4),"",SUMPRODUCT((Amortissements!$A$5:$A$40=$C$3)*(Amortissements!$H$4:$L$4=H$7)*Amortissements!$H$5:$L$40))
B26: Amortissements en report (début d'année) | D26: =IF(D$7>YEAR($C$4),"",0) -> 0 | E26: =IF(E$7>YEAR($C$4),"",IF(ISNUMBER(D32),D32,D28)) -> 1834.69 | F26: =IF(F$7>YEAR($C$4),"",IF(ISNUMBER(E32),E32,E28)) -> 3824.3 | G26: =IF(G$7>YEAR($C$4),"",IF(ISNUMBER(F32),F32,F28)) | H26: =IF(H$7>YEAR($C$4),"",IF(ISNUMBER(G32),G32,G28))
B27: Amortissements utilisés | D27: =IF(D$7>YEAR($C$4),"",MIN(D25+D26,MAX(0,D24))) -> 3639.9 | E27: =IF(E$7>YEAR($C$4),"",MIN(E25+E26,MAX(0,E24))) -> 6682.8 | F27: =IF(F$7>YEAR($C$4),"",MIN(F25+F26,MAX(0,F24))) -> 2697.43 | G27: =IF(G$7>YEAR($C$4),"",MIN(G25+G26,MAX(0,G24))) | H27: =IF(H$7>YEAR($C$4),"",MIN(H25+H26,MAX(0,H24))) | I27: Un amortissement ne peut pas créer de déficit : l'excédent est reporté sans limite de durée.
B28: Amortissements en report (fin d'année, calcul de l'outil) | D28: =IF(D$7>YEAR($C$4),"",D26+D25-D27) -> 2111.1489 | E28: =IF(E$7>YEAR($C$4),"",E26+E25-E27) -> 4449.2267 | F28: =IF(F$7>YEAR($C$4),"",F26+F25-F27) -> 10515.257 | G28: =IF(G$7>YEAR($C$4),"",G26+G25-G27) | H28: =IF(H$7>YEAR($C$4),"",H26+H25-H27) | I28: Année en cours : estimation, la dotation est annuelle alors que les recettes ne sont saisies que jusqu'à la date de mise à jour.
B29: Résultat fiscal estimé | D29: =IF(D$7>YEAR($C$4),"",D24-D27) -> 0 | E29: =IF(E$7>YEAR($C$4),"",E24-E27) -> 0 | F29: =IF(F$7>YEAR($C$4),"",F24-F27) -> 0 | G29: =IF(G$7>YEAR($C$4),"",G24-G27) | H29: =IF(H$7>YEAR($C$4),"",H24-H27) | I29: Négatif = déficit imputable sur les revenus de location meublée des 10 années suivantes.
B30: Dépenses à qualifier (non retenues) | D30: =IF(D$7>YEAR($C$4),"",-SUMIFS(Journal!$K$5:$K$1004,Journal!$C$5:$C$1004,$C$3,Journal!$B$5:$B$1004,D$7,Journal!$I$5:$I$1004,"À valider")) -> 395.25 | E30: =IF(E$7>YEAR($C$4),"",-SUMIFS(Journal!$K$5:$K$1004,Journal!$C$5:$C$1004,$C$3,Journal!$B$5:$B$1004,E$7,Journal!$I$5:$I$1004,"À valider")) -> 0 | F30: =IF(F$7>YEAR($C$4),"",-SUMIFS(Journal!$K$5:$K$1004,Journal!$C$5:$C$1004,$C$3,Journal!$B$5:$B$1004,F$7,Journal!$I$5:$I$1004,"À valider")) -> 0 | G30: =IF(G$7>YEAR($C$4),"",-SUMIFS(Journal!$K$5:$K$1004,Journal!$C$5:$C$1004,$C$3,Journal!$B$5:$B$1004,G$7,Journal!$I$5:$I$1004,"À valider")) | H30: =IF(H$7>YEAR($C$4),"",-SUMIFS(Journal!$K$5:$K$1004,Journal!$C$5:$C$1004,$C$3,Journal!$B$5:$B$1004,H$7,Journal!$I$5:$I$1004,"À valider")) | I30: À valider avec le comptable (onglet Journal, lignes surlignées).
B31: Investissements de l'année (à amortir) | D31: =IF(D$7>YEAR($C$4),"",-SUMIFS(Journal!$K$5:$K$1004,Journal!$C$5:$C$1004,$C$3,Journal!$B$5:$B$1004,D$7,Journal!$I$5:$I$1004,"À amortir")) -> 1076.01 | E31: =IF(E$7>YEAR($C$4),"",-SUMIFS(Journal!$K$5:$K$1004,Journal!$C$5:$C$1004,$C$3,Journal!$B$5:$B$1004,E$7,Journal!$I$5:$I$1004,"À amortir")) -> 1590.11 | F31: =IF(F$7>YEAR($C$4),"",-SUMIFS(Journal!$K$5:$K$1004,Journal!$C$5:$C$1004,$C$3,Journal!$B$5:$B$1004,F$7,Journal!$I$5:$I$1004,"À amortir")) -> 0 | G31: =IF(G$7>YEAR($C$4),"",-SUMIFS(Journal!$K$5:$K$1004,Journal!$C$5:$C$1004,$C$3,Journal!$B$5:$B$1004,G$7,Journal!$I$5:$I$1004,"À amortir")) | H31: =IF(H$7>YEAR($C$4),"",-SUMIFS(Journal!$K$5:$K$1004,Journal!$C$5:$C$1004,$C$3,Journal!$B$5:$B$1004,H$7,Journal!$I$5:$I$1004,"À amortir")) | I31: À reporter dans l'onglet Amortissements.
B32: Stock reporté retenu par le comptable (comptes déposés) | D32: 1834.69 | E32: 3824.3 | I32: À saisir chaque année depuis les comptes du comptable. S'il est renseigné, c'est ce stock qui sert de point de départ l'année suivante (il fait foi pour la déclaration).
B33: 2. Trésorerie (cash-flow)
B34: Encaissements (recettes) | D34: =IF(D$7>YEAR($C$4),"",SUMIFS(Journal!$K$5:$K$1004,Journal!$C$5:$C$1004,$C$3,Journal!$B$5:$B$1004,D$7,Journal!$H$5:$H$1004,"Recette")) -> 8366.76 | E34: =IF(E$7>YEAR($C$4),"",SUMIFS(Journal!$K$5:$K$1004,Journal!$C$5:$C$1004,$C$3,Journal!$B$5:$B$1004,E$7,Journal!$H$5:$H$1004,"Recette")) -> 13703.15 | F34: =IF(F$7>YEAR($C$4),"",SUMIFS(Journal!$K$5:$K$1004,Journal!$C$5:$C$1004,$C$3,Journal!$B$5:$B$1004,F$7,Journal!$H$5:$H$1004,"Recette")) -> 11432.62 | G34: =IF(G$7>YEAR($C$4),"",SUMIFS(Journal!$K$5:$K$1004,Journal!$C$5:$C$1004,$C$3,Journal!$B$5:$B$1004,G$7,Journal!$H$5:$H$1004,"Recette")) | H34: =IF(H$7>YEAR($C$4),"",SUMIFS(Journal!$K$5:$K$1004,Journal!$C$5:$C$1004,$C$3,Journal!$B$5:$B$1004,H$7,Journal!$H$5:$H$1004,"Recette"))
B35: Dépenses payées (hors prêt) | D35: =IF(D$7>YEAR($C$4),"",-SUMIFS(Journal!$K$5:$K$1004,Journal!$C$5:$C$1004,$C$3,Journal!$B$5:$B$1004,D$7,Journal!$H$5:$H$1004,"Dépense")) -> 5021.99 | E35: =IF(E$7>YEAR($C$4),"",-SUMIFS(Journal!$K$5:$K$1004,Journal!$C$5:$C$1004,$C$3,Journal!$B$5:$B$1004,E$7,Journal!$H$5:$H$1004,"Dépense")) -> 6690.74 | F35: =IF(F$7>YEAR($C$4),"",-SUMIFS(Journal!$K$5:$K$1004,Journal!$C$5:$C$1004,$C$3,Journal!$B$5:$B$1004,F$7,Journal!$H$5:$H$1004,"Dépense")) -> 7229.68 | G35: =IF(G$7>YEAR($C$4),"",-SUMIFS(Journal!$K$5:$K$1004,Journal!$C$5:$C$1004,$C$3,Journal!$B$5:$B$1004,G$7,Journal!$H$5:$H$1004,"Dépense")) | H35: =IF(H$7>YEAR($C$4),"",-SUMIFS(Journal!$K$5:$K$1004,Journal!$C$5:$C$1004,$C$3,Journal!$B$5:$B$1004,H$7,Journal!$H$5:$H$1004,"Dépense"))
B36: Échéances de prêt (période louée) | D36: =IF(D$7>YEAR($C$4),"",SUMIFS(Échéancier!$I$5:$I$300,Échéancier!$J$5:$J$300,$C$3,Échéancier!$D$5:$D$300,D$7,Échéancier!$K$5:$K$300,1,Échéancier!$C$5:$C$300,"<="&$C$4)) -> 5889.26 | E36: =IF(E$7>YEAR($C$4),"",SUMIFS(Échéancier!$I$5:$I$300,Échéancier!$J$5:$J$300,$C$3,Échéancier!$D$5:$D$300,E$7,Échéancier!$K$5:$K$300,1,Échéancier!$C$5:$C$300,"<="&$C$4)) -> 10095.91 | F36: =IF(F$7>YEAR($C$4),"",SUMIFS(Échéancier!$I$5:$I$300,Échéancier!$J$5:$J$300,$C$3,Échéancier!$D$5:$D$300,F$7,Échéancier!$K$5:$K$300,1,Échéancier!$C$5:$C$300,"<="&$C$4)) -> 8413.25 | G36: =IF(G$7>YEAR($C$4),"",SUMIFS(Échéancier!$I$5:$I$300,Échéancier!$J$5:$J$300,$C$3,Échéancier!$D$5:$D$300,G$7,Échéancier!$K$5:$K$300,1,Échéancier!$C$5:$C$300,"<="&$C$4)) | H36: =IF(H$7>YEAR($C$4),"",SUMIFS(Échéancier!$I$5:$I$300,Échéancier!$J$5:$J$300,$C$3,Échéancier!$D$5:$D$300,H$7,Échéancier!$K$5:$K$300,1,Échéancier!$C$5:$C$300,"<="&$C$4))
B37: dont capital remboursé | D37: =IF(D$7>YEAR($C$4),"",SUMIFS(Échéancier!$F$5:$F$300,Échéancier!$J$5:$J$300,$C$3,Échéancier!$D$5:$D$300,D$7,Échéancier!$K$5:$K$300,1,Échéancier!$C$5:$C$300,"<="&$C$4)) -> 4713.13 | E37: =IF(E$7>YEAR($C$4),"",SUMIFS(Échéancier!$F$5:$F$300,Échéancier!$J$5:$J$300,$C$3,Échéancier!$D$5:$D$300,E$7,Échéancier!$K$5:$K$300,1,Échéancier!$C$5:$C$300,"<="&$C$4)) -> 8176.19 | F37: =IF(F$7>YEAR($C$4),"",SUMIFS(Échéancier!$F$5:$F$300,Échéancier!$J$5:$J$300,$C$3,Échéancier!$D$5:$D$300,F$7,Échéancier!$K$5:$K$300,1,Échéancier!$C$5:$C$300,"<="&$C$4)) -> 6907.74 | G37: =IF(G$7>YEAR($C$4),"",SUMIFS(Échéancier!$F$5:$F$300,Échéancier!$J$5:$J$300,$C$3,Échéancier!$D$5:$D$300,G$7,Échéancier!$K$5:$K$300,1,Échéancier!$C$5:$C$300,"<="&$C$4)) | H37: =IF(H$7>YEAR($C$4),"",SUMIFS(Échéancier!$F$5:$F$300,Échéancier!$J$5:$J$300,$C$3,Échéancier!$D$5:$D$300,H$7,Échéancier!$K$5:$K$300,1,Échéancier!$C$5:$C$300,"<="&$C$4))
B38: Cash-flow | D38: =IF(D$7>YEAR($C$4),"",D34-D35-D36) -> -2544.49 | E38: =IF(E$7>YEAR($C$4),"",E34-E35-E36) -> -3083.5 | F38: =IF(F$7>YEAR($C$4),"",F34-F35-F36) -> -4210.31 | G38: =IF(G$7>YEAR($C$4),"",G34-G35-G36) | H38: =IF(H$7>YEAR($C$4),"",H34-H35-H36)
B39: Mois de location sur la période | D39: =IF(D$7>YEAR($C$4),"",MAX(0,MIN(DATE(D$7,12,31),EOMONTH($C$4,0))-MAX(DATE(D$7,1,1),IFERROR(INDEX(Biens!$O$5:$O$30,MATCH(Synthèse!$C$3,Biens!$A$5:$A$30,0)),0))+1)/(365/12)) -> 7.4958904 | E39: =IF(E$7>YEAR($C$4),"",MAX(0,MIN(DATE(E$7,12,31),EOMONTH($C$4,0))-MAX(DATE(E$7,1,1),IFERROR(INDEX(Biens!$O$5:$O$30,MATCH(Synthèse!$C$3,Biens!$A$5:$A$30,0)),0))+1)/(365/12)) -> 12 | F39: =IF(F$7>YEAR($C$4),"",MAX(0,MIN(DATE(F$7,12,31),EOMONTH($C$4,0))-MAX(DATE(F$7,1,1),IFERROR(INDEX(Biens!$O$5:$O$30,MATCH(Synthèse!$C$3,Biens!$A$5:$A$30,0)),0))+1)/(365/12)) -> 9.9945205 | G39: =IF(G$7>YEAR($C$4),"",MAX(0,MIN(DATE(G$7,12,31),EOMONTH($C$4,0))-MAX(DATE(G$7,1,1),IFERROR(INDEX(Biens!$O$5:$O$30,MATCH(Synthèse!$C$3,Biens!$A$5:$A$30,0)),0))+1)/(365/12)) | H39: =IF(H$7>YEAR($C$4),"",MAX(0,MIN(DATE(H$7,12,31),EOMONTH($C$4,0))-MAX(DATE(H$7,1,1),IFERROR(INDEX(Biens!$O$5:$O$30,MATCH(Synthèse!$C$3,Biens!$A$5:$A$30,0)),0))+1)/(365/12)) | I39: Jusqu'à la fin du mois de la date de mise à jour (C4), les loyers étant payés d'avance.
B40: Cash-flow mensuel moyen | D40: =IF(D$7>YEAR($C$4),"",IF(D39>0,D38/D39,0)) -> -339.45133 | E40: =IF(E$7>YEAR($C$4),"",IF(E39>0,E38/E39,0)) -> -256.95833 | F40: =IF(F$7>YEAR($C$4),"",IF(F39>0,F38/F39,0)) -> -421.26183 | G40: =IF(G$7>YEAR($C$4),"",IF(G39>0,G38/G39,0)) | H40: =IF(H$7>YEAR($C$4),"",IF(H39>0,H38/H39,0))
B41: Enrichissement (cash-flow + capital remboursé) | D41: =IF(D$7>YEAR($C$4),"",D38+D37) -> 2168.64 | E41: =IF(E$7>YEAR($C$4),"",E38+E37) -> 5092.69 | F41: =IF(F$7>YEAR($C$4),"",F38+F37) -> 2697.43 | G41: =IF(G$7>YEAR($C$4),"",G38+G37) | H41: =IF(H$7>YEAR($C$4),"",H38+H37)
B43: 3. Rentabilité
B44: Coût total d'acquisition | D44: =IF(D$7>YEAR($C$4),"",IFERROR(INDEX(Biens!$M$5:$M$30,MATCH(Synthèse!$C$3,Biens!$A$5:$A$30,0)),0)) -> 268158.99 | E44: =IF(E$7>YEAR($C$4),"",IFERROR(INDEX(Biens!$M$5:$M$30,MATCH(Synthèse!$C$3,Biens!$A$5:$A$30,0)),0)) -> 268158.99 | F44: =IF(F$7>YEAR($C$4),"",IFERROR(INDEX(Biens!$M$5:$M$30,MATCH(Synthèse!$C$3,Biens!$A$5:$A$30,0)),0)) -> 268158.99 | G44: =IF(G$7>YEAR($C$4),"",IFERROR(INDEX(Biens!$M$5:$M$30,MATCH(Synthèse!$C$3,Biens!$A$5:$A$30,0)),0)) | H44: =IF(H$7>YEAR($C$4),"",IFERROR(INDEX(Biens!$M$5:$M$30,MATCH(Synthèse!$C$3,Biens!$A$5:$A$30,0)),0))
B45: Loyers hors charges annualisés | D45: =IF(D$7>YEAR($C$4),"",IF(D39>0,D10/D39*12,0)) -> 12314.428 | E45: =IF(E$7>YEAR($C$4),"",IF(E39>0,E10/E39*12,0)) -> 12387.89 | F45: =IF(F$7>YEAR($C$4),"",IF(F39>0,F10/F39*12,0)) -> 12621.22 | G45: =IF(G$7>YEAR($C$4),"",IF(G39>0,G10/G39*12,0)) | H45: =IF(H$7>YEAR($C$4),"",IF(H39>0,H10/H39*12,0))
...

Sheet Journal
A1: Journal des mouvements
A2: Une ligne par mouvement d'argent (agence, banque ou autre). Montant toujours positif, sauf annulation ou remise. Saisissez les colonnes A, C à G et M à O : les colonnes grises se calculent.
A4: Date | B4: Année | C4: Bien | D4: Compte | E4: Catégorie | F4: Libellé | G4: Montant | H4: Sens | I4: Traitement fiscal | J4: Groupe | K4: Montant au résultat | L4: Flux de trésorerie | M4: Pièce justificative | N4: Source | O4: Commentaire
A5: 45426 | B5: =IF(A5="","",YEAR(A5)) -> 2024 | C5: APPART-01 | D5: Agence | E5: Honoraires de mise en location | F5: HONORAIRES EDL | G5: 140.04 | H5: =IF(E5="","",IFERROR(INDEX(Catégories!$B$5:$B$60,MATCH(E5,Catégories!$A$5:$A$60,0)),"?")) -> Dépense | I5: =IF(E5="","",IFERROR(INDEX(Catégories!$C$5:$C$60,MATCH(E5,Catégories!$A$5:$A$60,0)),"?")) -> Déductible | J5: =IF(E5="","",IFERROR(INDEX(Catégories!$D$5:$D$60,MATCH(E5,Catégories!$A$5:$A$60,0)),"?")) -> Frais de gestion | K5: =IF(H5="Recette",G5,IF(H5="Dépense",-G5,0)) -> -140.04 | L5: =IF(E5="",0,G5*IFERROR(INDEX(Catégories!$E$5:$E$60,MATCH(E5,Catégories!$A$5:$A$60,0)),0)) -> -140.04 | M5: Bien/04_Agence/2024-05_2026-11_AGENCE_Grand-livre-proprietaire.pdf | N5: Grand livre agence
A6: 45426 | B6: =IF(A6="","",YEAR(A6)) -> 2024 | C6: APPART-01 | D6: Agence | E6: Honoraires de mise en location | F6: TVA HONORAIRES EDL | G6: 28 | H6: =IF(E6="","",IFERROR(INDEX(Catégories!$B$5:$B$60,MATCH(E6,Catégories!$A$5:$A$60,0)),"?")) -> Dépense | I6: =IF(E6="","",IFERROR(INDEX(Catégories!$C$5:$C$60,MATCH(E6,Catégories!$A$5:$A$60,0)),"?")) -> Déductible | J6: =IF(E6="","",IFERROR(INDEX(Catégories!$D$5:$D$60,MATCH(E6,Catégories!$A$5:$A$60,0)),"?")) -> Frais de gestion | K6: =IF(H6="Recette",G6,IF(H6="Dépense",-G6,0)) -> -28 | L6: =IF(E6="",0,G6*IFERROR(INDEX(Catégories!$E$5:$E$60,MATCH(E6,Catégories!$A$5:$A$60,0)),0)) -> -28 | M6: Bien/04_Agence/2024-05_2026-11_AGENCE_Grand-livre-proprietaire.pdf | N6: Grand livre agence
A7: 45426 | B7: =IF(A7="","",YEAR(A7)) -> 2024 | C7: APPART-01 | D7: Agence | E7: Honoraires de mise en location | F7: HONORAIRES LOCATION | G7: 369.86 | H7: =IF(E7="","",IFERROR(INDEX(Catégories!$B$5:$B$60,MATCH(E7,Catégories!$A$5:$A$60,0)),"?")) -> Dépense | I7: =IF(E7="","",IFERROR(INDEX(Catégories!$C$5:$C$60,MATCH(E7,Catégories!$A$5:$A$60,0)),"?")) -> Déductible | J7: =IF(E7="","",IFERROR(INDEX(Catégories!$D$5:$D$60,MATCH(E7,Catégories!$A$5:$A$60,0)),"?")) -> Frais de gestion | K7: =IF(H7="Recette",G7,IF(H7="Dépense",-G7,0)) -> -369.86 | L7: =IF(E7="",0,G7*IFERROR(INDEX(Catégories!$E$5:$E$60,MATCH(E7,Catégories!$A$5:$A$60,0)),0)) -> -369.86 | M7: Bien/04_Agence/2024-05_2026-11_AGENCE_Grand-livre-proprietaire.pdf | N7: Grand livre agence
A8: 45426 | B8: =IF(A8="","",YEAR(A8)) -> 2024 | C8: APPART-01 | D8: Agence | E8: Honoraires de mise en location | F8: TVA HONORAIRES LOCATION | G8: 73.97 | H8: =IF(E8="","",IFERROR(INDEX(Catégories!$B$5:$B$60,MATCH(E8,Catégories!$A$5:$A$60,0)),"?")) -> Dépense | I8: =IF(E8="","",IFERROR(INDEX(Catégories!$C$5:$C$60,MATCH(E8,Catégories!$A$5:$A$60,0)),"?")) -> Déductible | J8: =IF(E8="","",IFERROR(INDEX(Catégories!$D$5:$D$60,MATCH(E8,Catégories!$A$5:$A$60,0)),"?")) -> Frais de gestion | K8: =IF(H8="Recette",G8,IF(H8="Dépense",-G8,0)) -> -73.97 | L8: =IF(E8="",0,G8*IFERROR(INDEX(Catégories!$E$5:$E$60,MATCH(E8,Catégories!$A$5:$A$60,0)),0)) -> -73.97 | M8: Bien/04_Agence/2024-05_2026-11_AGENCE_Grand-livre-proprietaire.pdf | N8: Grand livre agence
A9: 45427 | B9: =IF(A9="","",YEAR(A9)) -> 2024 | C9: APPART-01 | D9: Agence | E9: Loyer hors charges | F9: LOYER PRINCIPAL (18/05/2024 - 31/05/2024) | G9: 466.2 | H9: =IF(E9="","",IFERROR(INDEX(Catégories!$B$5:$B$60,MATCH(E9,Catégories!$A$5:$A$60,0)),"?")) -> Recette | I9: =IF(E9="","",IFERROR(INDEX(Catégories!$C$5:$C$60,MATCH(E9,Catégories!$A$5:$A$60,0)),"?")) -> Imposable | J9: =IF(E9="","",IFERROR(INDEX(Catégories!$D$5:$D$60,MATCH(E9,Catégories!$A$5:$A$60,0)),"?")) -> Loyers | K9: =IF(H9="Recette",G9,IF(H9="Dépense",-G9,0)) -> 466.2 | L9: =IF(E9="",0,G9*IFERROR(INDEX(Catégories!$E$5:$E$60,MATCH(E9,Catégories!$A$5:$A$60,0)),0)) -> 466.2 | M9: Bien/04_Agence/2024-05_2026-11_AGENCE_Grand-livre-proprietaire.pdf | N9: Grand livre agence
A10: 45427 | B10: =IF(A10="","",YEAR(A10)) -> 2024 | C10: APPART-01 | D10: Agence | E10: Honoraires de gestion | F10: HONORAIRES GESTION LOYER PRINCIPAL 6.00% | G10: 27.97 | H10: =IF(E10="","",IFERROR(INDEX(Catégories!$B$5:$B$60,MATCH(E10,Catégories!$A$5:$A$60,0)),"?")) -> Dépense | I10: =IF(E10="","",IFERROR(INDEX(Catégories!$C$5:$C$60,MATCH(E10,Catégories!$A$5:$A$60,0)),"?")) -> Déductible | J10: =IF(E10="","",IFERROR(INDEX(Catégories!$D$5:$D$60,MATCH(E10,Catégories!$A$5:$A$60,0)),"?")) -> Frais de gestion | K10: =IF(H10="Recette",G10,IF(H10="Dépense",-G10,0)) -> -27.97 | L10: =IF(E10="",0,G10*IFERROR(INDEX(Catégories!$E$5:$E$60,MATCH(E10,Catégories!$A$5:$A$60,0)),0)) -> -27.97 | M10: Bien/04_Agence/2024-05_2026-11_AGENCE_Grand-livre-proprietaire.pdf | N10: Grand livre agence
A11: 45427 | B11: =IF(A11="","",YEAR(A11)) -> 2024 | C11: APPART-01 | D11: Agence | E11: Honoraires de gestion | F11: TVA HONORAIRES GESTION LOYER PRINCIPAL | G11: 5.6 | H11: =IF(E11="","",IFERROR(INDEX(Catégories!$B$5:$B$60,MATCH(E11,Catégories!$A$5:$A$60,0)),"?")) -> Dépense | I11: =IF(E11="","",IFERROR(INDEX(Catégories!$C$5:$C$60,MATCH(E11,Catégories!$A$5:$A$60,0)),"?")) -> Déductible | J11: =IF(E11="","",IFERROR(INDEX(Catégories!$D$5:$D$60,MATCH(E11,Catégories!$A$5:$A$60,0)),"?")) -> Frais de gestion | K11: =IF(H11="Recette",G11,IF(H11="Dépense",-G11,0)) -> -5.6 | L11: =IF(E11="",0,G11*IFERROR(INDEX(Catégories!$E$5:$E$60,MATCH(E11,Catégories!$A$5:$A$60,0)),0)) -> -5.6 | M11: Bien/04_Agence/2024-05_2026-11_AGENCE_Grand-livre-proprietaire.pdf | N11: Grand livre agence
A12: 45427 | B12: =IF(A12="","",YEAR(A12)) -> 2024 | C12: APPART-01 | D12: Agence | E12: Provisions sur charges | F12: PROVISIONS CHARGES (18/05/2024 - 31/05/2024) | G12: 37.8 | H12: =IF(E12="","",IFERROR(INDEX(Catégories!$B$5:$B$60,MATCH(E12,Catégories!$A$5:$A$60,0)),"?")) -> Recette | I12: =IF(E12="","",IFERROR(INDEX(Catégories!$C$5:$C$60,MATCH(E12,Catégories!$A$5:$A$60,0)),"?")) -> Imposable | J12: =IF(E12="","",IFERROR(INDEX(Catégories!$D$5:$D$60,MATCH(E12,Catégories!$A$5:$A$60,0)),"?")) -> Charges refacturées | K12: =IF(H12="Recette",G12,IF(H12="Dépense",-G12,0)) -> 37.8 | L12: =IF(E12="",0,G12*IFERROR(INDEX(Catégories!$E$5:$E$60,MATCH(E12,Catégories!$A$5:$A$60,0)),0)) -> 37.8 | M12: Bien/04_Agence/2024-05_2026-11_AGENCE_Grand-livre-proprietaire.pdf | N12: Grand livre agence
A13: 45427 | B13: =IF(A13="","",YEAR(A13)) -> 2024 | C13: APPART-01 | D13: Agence | E13: Honoraires de gestion | F13: HONORAIRES GESTION PROVISIONS CHARGES 6.00% | G13: 2.27 | H13: =IF(E13="","",IFERROR(INDEX(Catégories!$B$5:$B$60,MATCH(E13,Catégories!$A$5:$A$60,0)),"?")) -> Dépense | I13: =IF(E13="","",IFERROR(INDEX(Catégories!$C$5:$C$60,MATCH(E13,Catégories!$A$5:$A$60,0)),"?")) -> Déductible | J13: =IF(E13="","",IFERROR(INDEX(Catégories!$D$5:$D$60,MATCH(E13,Catégories!$A$5:$A$60,0)),"?")) -> Frais de gestion | K13: =IF(H13="Recette",G13,IF(H13="Dépense",-G13,0)) -> -2.27 | L13: =IF(E13="",0,G13*IFERROR(INDEX(Catégories!$E$5:$E$60,MATCH(E13,Catégories!$A$5:$A$60,0)),0)) -> -2.27 | M13: Bien/04_Agence/2024-05_2026-11_AGENCE_Grand-livre-proprietaire.pdf | N13: Grand livre agence
A14: 45427 | B14: =IF(A14="","",YEAR(A14)) -> 2024 | C14: APPART-01 | D14: Agence | E14: Honoraires de gestion | F14: TVA HONORAIRES GESTION PROVISIONS CHARGES | G14: 0.46 | H14: =IF(E14="","",IFERROR(INDEX(Catégories!$B$5:$B$60,MATCH(E14,Catégories!$A$5:$A$60,0)),"?")) -> Dépense | I14: =IF(E14="","",IFERROR(INDEX(Catégories!$C$5:$C$60,MATCH(E14,Catégories!$A$5:$A$60,0)),"?")) -> Déductible | J14: =IF(E14="","",IFERROR(INDEX(Catégories!$D$5:$D$60,MATCH(E14,Catégories!$A$5:$A$60,0)),"?")) -> Frais de gestion | K14: =IF(H14="Recette",G14,IF(H14="Dépense",-G14,0)) -> -0.46 | L14: =IF(E14="",0,G14*IFERROR(INDEX(Catégories!$E$5:$E$60,MATCH(E14,Catégories!$A$5:$A$60,0)),0)) -> -0.46 | M14: Bien/04_Agence/2024-05_2026-11_AGENCE_Grand-livre-proprietaire.pdf | N14: Grand livre agence
A15: 45427 | B15: =IF(A15="","",YEAR(A15)) -> 2024 | C15: APPART-01 | D15: Agence | E15: Dépôt de garantie restitué | F15: DEPOT DE GARANTIE LOCATAIRE - debit | G15: 2064.6 | H15: =IF(E15="","",IFERROR(INDEX(Catégories!$B$5:$B$60,MATCH(E15,Catégories!$A$5:$A$60,0)),"?")) -> Neutre | I15: =IF(E15="","",IFERROR(INDEX(Catégories!$C$5:$C$60,MATCH(E15,Catégories!$A$5:$A$60,0)),"?")) -> Non fiscal | J15: =IF(E15="","",IFERROR(INDEX(Catégories!$D$5:$D$60,MATCH(E15,Catégories!$A$5:$A$60,0)),"?")) -> Dépôt de garantie | K15: =IF(H15="Recette",G15,IF(H15="Dépense",-G15,0)) -> 0 | L15: =IF(E15="",0,G15*IFERROR(INDEX(Catégories!$E$5:$E$60,MATCH(E15,Catégories!$A$5:$A$60,0)),0)) -> -2064.6 | M15: Bien/04_Agence/2024-05_2026-11_AGENCE_Grand-livre-proprietaire.pdf | N15: Grand livre agence | O15: Écriture de passage à l'agence (le dépôt a été versé directement au propriétaire)
A16: 45427 | B16: =IF(A16="","",YEAR(A16)) -> 2024 | C16: APPART-01 | D16: Agence | E16: Dépôt de garantie reçu | F16: DEPOT GARANTIE PROPRIETAIRE/LOCATAIRE - credit | G16: 2064.6 | H16: =IF(E16="","",IFERROR(INDEX(Catégories!$B$5:$B$60,MATCH(E16,Catégories!$A$5:$A$60,0)),"?")) -> Neutre | I16: =IF(E16="","",IFERROR(INDEX(Catégories!$C$5:$C$60,MATCH(E16,Catégories!$A$5:$A$60,0)),"?")) -> Non fiscal | J16: =IF(E16="","",IFERROR(INDEX(Catégories!$D$5:$D$60,MATCH(E16,Catégories!$A$5:$A$60,0)),"?")) -> Dépôt de garantie | K16: =IF(H16="Recette",G16,IF(H16="Dépense",-G16,0)) -> 0 | L16: =IF(E16="",0,G16*IFERROR(INDEX(Catégories!$E$5:$E$60,MATCH(E16,Catégories!$A$5:$A$60,0)),0)) -> 2064.6 | M16: Bien/04_Agence/2024-05_2026-11_AGENCE_Grand-livre-proprietaire.pdf | N16: Grand livre agence | O16: Écriture de passage à l'agence (le dépôt a été versé directement au propriétaire)
A17: 45427 | B17: =IF(A17="","",YEAR(A17)) -> 2024 | C17: APPART-01 | D17: Banque | E17: Dépôt de garantie reçu | F17: VIR INST LOCATAIRE DEPOT DE GARANTIE LOCATAIRE | G17: 2064.6 | H17: =IF(E17="","",IFERROR(INDEX(Catégories!$B$5:$B$60,MATCH(E17,Catégories!$A$5:$A$60,0)),"?")) -> Neutre | I17: =IF(E17="","",IFERROR(INDEX(Catégories!$C$5:$C$60,MATCH(E17,Catégories!$A$5:$A$60,0)),"?")) -> Non fiscal | J17: =IF(E17="","",IFERROR(INDEX(Catégories!$D$5:$D$60,MATCH(E17,Catégories!$A$5:$A$60,0)),"?")) -> Dépôt de garantie | K17: =IF(H17="Recette",G17,IF(H17="Dépense",-G17,0)) -> 0 | L17: =IF(E17="",0,G17*IFERROR(INDEX(Catégories!$E$5:$E$60,MATCH(E17,Catégories!$A$5:$A$60,0)),0)) -> 2064.6 | M17: Banque/Banque_Exempleville_Revenus-Depenses_2024-2026.xlsx | N17: Relevé BANQUE | O17: Dépôt de garantie versé directement par le locataire : à restituer à son départ
A18: 45427 | B18: =IF(A18="","",YEAR(A18)) -> 2024 | C18: APPART-01 | D18: Banque | E18: À qualifier | F18: VIR SEPA FACTURE - | G18: 395.25 | H18: =IF(E18="","",IFERROR(INDEX(Catégories!$B$5:$B$60,MATCH(E18,Catégories!$A$5:$A$60,0)),"?")) -> Dépense | I18: =IF(E18="","",IFERROR(INDEX(Catégories!$C$5:$C$60,MATCH(E18,Catégories!$A$5:$A$60,0)),"?")) -> À valider | J18: =IF(E18="","",IFERROR(INDEX(Catégories!$D$5:$D$60,MATCH(E18,Catégories!$A$5:$A$60,0)),"?")) -> À qualifier | K18: =IF(H18="Recette",G18,IF(H18="Dépense",-G18,0)) -> -395.25 | L18: =IF(E18="",0,G18*IFERROR(INDEX(Catégories!$E$5:$E$60,MATCH(E18,Catégories!$A$5:$A$60,0)),0)) -> -395.25 | M18: Banque/Banque_Exempleville_Revenus-Depenses_2024-2026.xlsx | N18: Relevé BANQUE | O18: Volet du Velux refait avant la location. Non repris par le comptable en 2024 : à lui soumettre (charge ou immobilisation)
A19: 45446 | B19: =IF(A19="","",YEAR(A19)) -> 2024 | C19: APPART-01 | D19: Agence | E19: Loyer hors charges | F19: LOYER PRINCIPAL (01/06/2024 - 30/06/2024) | G19: 1032.3 | H19: =IF(E19="","",IFERROR(INDEX(Catégories!$B$5:$B$60,MATCH(E19,Catégories!$A$5:$A$60,0)),"?")) -> Recette | I19: =IF(E19="","",IFERROR(INDEX(Catégories!$C$5:$C$60,MATCH(E19,Catégories!$A$5:$A$60,0)),"?")) -> Imposable | J19: =IF(E19="","",IFERROR(INDEX(Catégories!$D$5:$D$60,MATCH(E19,Catégories!$A$5:$A$60,0)),"?")) -> Loyers | K19: =IF(H19="Recette",G19,IF(H19="Dépense",-G19,0)) -> 1032.3 | L19: =IF(E19="",0,G19*IFERROR(INDEX(Catégories!$E$5:$E$60,MATCH(E19,Catégories!$A$5:$A$60,0)),0)) -> 1032.3 | M19: Bien/04_Agence/2024-05_2026-11_AGENCE_Grand-livre-proprietaire.pdf | N19: Grand livre agence
A20: 45446 | B20: =IF(A20="","",YEAR(A20)) -> 2024 | C20: APPART-01 | D20: Agence | E20: Honoraires de gestion | F20: HONORAIRES GESTION LOYER PRINCIPAL 6.00% | G20: 61.94 | H20: =IF(E20="","",IFERROR(INDEX(Catégories!$B$5:$B$60,MATCH(E20,Catégories!$A$5:$A$60,0)),"?")) -> Dépense | I20: =IF(E20="","",IFERROR(INDEX(Catégories!$C$5:$C$60,MATCH(E20,Catégories!$A$5:$A$60,0)),"?")) -> Déductible | J20: =IF(E20="","",IFERROR(INDEX(Catégories!$D$5:$D$60,MATCH(E20,Catégories!$A$5:$A$60,0)),"?")) -> Frais de gestion | K20: =IF(H20="Recette",G20,IF(H20="Dépense",-G20,0)) -> -61.94 | L20: =IF(E20="",0,G20*IFERROR(INDEX(Catégories!$E$5:$E$60,MATCH(E20,Catégories!$A$5:$A$60,0)),0)) -> -61.94 | M20: Bien/04_Agence/2024-05_2026-11_AGENCE_Grand-livre-proprietaire.pdf | N20: Grand livre agence
A21: 45446 | B21: =IF(A21="","",YEAR(A21)) -> 2024 | C21: APPART-01 | D21: Agence | E21: Honoraires de gestion | F21: TVA HONORAIRES GESTION LOYER PRINCIPAL | G21: 12.39 | H21: =IF(E21="","",IFERROR(INDEX(Catégories!$B$5:$B$60,MATCH(E21,Catégories!$A$5:$A$60,0)),"?")) -> Dépense | I21: =IF(E21="","",IFERROR(INDEX(Catégories!$C$5:$C$60,MATCH(E21,Catégories!$A$5:$A$60,0)),"?")) -> Déductible | J21: =IF(E21="","",IFERROR(INDEX(Catégories!$D$5:$D$60,MATCH(E21,Catégories!$A$5:$A$60,0)),"?")) -> Frais de gestion | K21: =IF(H21="Recette",G21,IF(H21="Dépense",-G21,0)) -> -12.39 | L21: =IF(E21="",0,G21*IFERROR(INDEX(Catégories!$E$5:$E$60,MATCH(E21,Catégories!$A$5:$A$60,0)),0)) -> -12.39 | M21: Bien/04_Agence/2024-05_2026-11_AGENCE_Grand-livre-proprietaire.pdf | N21: Grand livre agence
A22: 45446 | B22: =IF(A22="","",YEAR(A22)) -> 2024 | C22: APPART-01 | D22: Agence | E22: Provisions sur charges | F22: PROVISIONS CHARGES (01/06/2024 - 30/06/2024) | G22: 83.7 | H22: =IF(E22="","",IFERROR(INDEX(Catégories!$B$5:$B$60,MATCH(E22,Catégories!$A$5:$A$60,0)),"?")) -> Recette | I22: =IF(E22="","",IFERROR(INDEX(Catégories!$C$5:$C$60,MATCH(E22,Catégories!$A$5:$A$60,0)),"?")) -> Imposable | J22: =IF(E22="","",IFERROR(INDEX(Catégories!$D$5:$D$60,MATCH(E22,Catégories!$A$5:$A$60,0)),"?")) -> Charges refacturées | K22: =IF(H22="Recette",G22,IF(H22="Dépense",-G22,0)) -> 83.7 | L22: =IF(E22="",0,G22*IFERROR(INDEX(Catégories!$E$5:$E$60,MATCH(E22,Catégories!$A$5:$A$60,0)),0)) -> 83.7 | M22: Bien/04_Agence/2024-05_2026-11_AGENCE_Grand-livre-proprietaire.pdf | N22: Grand livre agence
A23: 45446 | B23: =IF(A23="","",YEAR(A23)) -> 2024 | C23: APPART-01 | D23: Agence | E23: Honoraires de gestion | F23: HONORAIRES GESTION PROVISIONS CHARGES 6.00% | G23: 5.02 | H23: =IF(E23="","",IFERROR(INDEX(Catégories!$B$5:$B$60,MATCH(E23,Catégories!$A$5:$A$60,0)),"?")) -> Dépense | I23: =IF(E23="","",IFERROR(INDEX(Catégories!$C$5:$C$60,MATCH(E23,Catégories!$A$5:$A$60,0)),"?")) -> Déductible | J23: =IF(E23="","",IFERROR(INDEX(Catégories!$D$5:$D$60,MATCH(E23,Catégories!$A$5:$A$60,0)),"?")) -> Frais de gestion | K23: =IF(H23="Recette",G23,IF(H23="Dépense",-G23,0)) -> -5.02 | L23: =IF(E23="",0,G23*IFERROR(INDEX(Catégories!$E$5:$E$60,MATCH(E23,Catégories!$A$5:$A$60,0)),0)) -> -5.02 | M23: Bien/04_Agence/2024-05_2026-11_AGENCE_Grand-livre-proprietaire.pdf | N23: Grand livre agence
A24: 45446 | B24: =IF(A24="","",YEAR(A24)) -> 2024 | C24: APPART-01 | D24: Agence | E24: Honoraires de gestion | F24: TVA HONORAIRES GESTION PROVISIONS CHARGES | G24: 1 | H24: =IF(E24="","",IFERROR(INDEX(Catégories!$B$5:$B$60,MATCH(E24,Catégories!$A$5:$A$60,0)),"?")) -> Dépense | I24: =IF(E24="","",IFERROR(INDEX(Catégories!$C$5:$C$60,MATCH(E24,Catégories!$A$5:$A$60,0)),"?")) -> Déductible | J24: =IF(E24="","",IFERROR(INDEX(Catégories!$D$5:$D$60,MATCH(E24,Catégories!$A$5:$A$60,0)),"?")) -> Frais de gestion | K24: =IF(H24="Recette",G24,IF(H24="Dépense",-G24,0)) -> -1 | L24: =IF(E24="",0,G24*IFERROR(INDEX(Catégories!$E$5:$E$60,MATCH(E24,Catégories!$A$5:$A$60,0)),0)) -> -1 | M24: Bien/04_Agence/2024-05_2026-11_AGENCE_Grand-livre-proprietaire.pdf | N24: Grand livre agence
A25: 45446 | B25: =IF(A25="","",YEAR(A25)) -> 2024 | C25: APPART-01 | D25: Agence | E25: Honoraires sur travaux | F25: HONORAIRES GESTION SUR TRAVAUX 3%TTC | G25: 6.4 | H25: =IF(E25="","",IFERROR(INDEX(Catégories!$B$5:$B$60,MATCH(E25,Catégories!$A$5:$A$60,0)),"?")) -> Dépense | I25: =IF(E25="","",IFERROR(INDEX(Catégories!$C$5:$C$60,MATCH(E25,Catégories!$A$5:$A$60,0)),"?")) -> Déductible | J25: =IF(E25="","",IFERROR(INDEX(Catégories!$D$5:$D$60,MATCH(E25,Catégories!$A$5:$A$60,0)),"?")) -> Frais de gestion | K25: =IF(H25="Recette",G25,IF(H25="Dépense",-G25,0)) -> -6.4 | L25: =IF(E25="",0,G25*IFERROR(INDEX(Catégories!$E$5:$E$60,MATCH(E25,Catégories!$A$5:$A$60,0)),0)) -> -6.4 | M25: Bien/04_Agence/2024-05_2026-11_AGENCE_Grand-livre-proprietaire.pdf | N25: Grand livre agence
A26: 45446 | B26: =IF(A26="","",YEAR(A26)) -> 2024 | C26: APPART-01 | D26: Agence | E26: Honoraires sur travaux | F26: TVA HONORAIRES GESTION SUR TRAVAUX 3%TTC | G26: 1.27 | H26: =IF(E26="","",IFERROR(INDEX(Catégories!$B$5:$B$60,MATCH(E26,Catégories!$A$5:$A$60,0)),"?")) -> Dépense | I26: =IF(E26="","",IFERROR(INDEX(Catégories!$C$5:$C$60,MATCH(E26,Catégories!$A$5:$A$60,0)),"?")) -> Déductible | J26: =IF(E26="","",IFERROR(INDEX(Catégories!$D$5:$D$60,MATCH(E26,Catégories!$A$5:$A$60,0)),"?")) -> Frais de gestion | K26: =IF(H26="Recette",G26,IF(H26="Dépense",-G26,0)) -> -1.27 | L26: =IF(E26="",0,G26*IFERROR(INDEX(Catégories!$E$5:$E$60,MATCH(E26,Catégories!$A$5:$A$60,0)),0)) -> -1.27 | M26: Bien/04_Agence/2024-05_2026-11_AGENCE_Grand-livre-proprietaire.pdf | N26: Grand livre agence
A27: 45446 | B27: =IF(A27="","",YEAR(A27)) -> 2024 | C27: APPART-01 | D27: Agence | E27: Entretien et réparations | F27: ROBINET CUISINE + PORTE CHAMBRE ARTISAN D | G27: 255.75 | H27: =IF(E27="","",IFERROR(INDEX(Catégories!$B$5:$B$60,MATCH(E27,Catégories!$A$5:$A$60,0)),"?")) -> Dépense | I27: =IF(E27="","",IFERROR(INDEX(Catégories!$C$5:$C$60,MATCH(E27,Catégories!$A$5:$A$60,0)),"?")) -> Déductible | J27: =IF(E27="","",IFERROR(INDEX(Catégories!$D$5:$D$60,MATCH(E27,Catégories!$A$5:$A$60,0)),"?")) -> Entretien et petit équipement | K27: =IF(H27="Recette",G27,IF(H27="Dépense",-G27,0)) -> -255.75 | L27: =IF(E27="",0,G27*IFERROR(INDEX(Catégories!$E$5:$E$60,MATCH(E27,Catégories!$A$5:$A$60,0)),0)) -> -255.75 | M27: Bien/04_Agence/2024-05_2026-11_AGENCE_Grand-livre-proprietaire.pdf | N27: Grand livre agence
A28: 45448 | B28: =IF(A28="","",YEAR(A28)) -> 2024 | C28: APPART-01 | D28: Agence | E28: Entretien et réparations | F28: reparation lave-linge ARTISAN C | G28: 109.74 | H28: =IF(E28="","",IFERROR(INDEX(Catégories!$B$5:$B$60,MATCH(E28,Catégories!$A$5:$A$60,0)),"?")) -> Dépense | I28: =IF(E28="","",IFERROR(INDEX(Catégories!$C$5:$C$60,MATCH(E28,Catégories!$A$5:$A$60,0)),"?")) -> Déductible | J28: =IF(E28="","",IFERROR(INDEX(Catégories!$D$5:$D$60,MATCH(E28,Catégories!$A$5:$A$60,0)),"?")) -> Entretien et petit équipement | K28: =IF(H28="Recette",G28,IF(H28="Dépense",-G28,0)) -> -109.74 | L28: =IF(E28="",0,G28*IFERROR(INDEX(Catégories!$E$5:$E$60,MATCH(E28,Catégories!$A$5:$A$60,0)),0)) -> -109.74 | M28: Bien/04_Agence/2024-05_2026-11_AGENCE_Grand-livre-proprietaire.pdf | N28: Grand livre agence
A29: 45448 | B29: =IF(A29="","",YEAR(A29)) -> 2024 | C29: APPART-01 | D29: Agence | E29: Honoraires sur travaux | F29: HONORAIRES GESTION TRAVAUX 3% TTC (ARTISAN C) | G29: 2.74 | H29: =IF(E29="","",IFERROR(INDEX(Catégories!$B$5:$B$60,MATCH(E29,Catégories!$A$5:$A$60,0)),"?")) -> Dépense | I29: =IF(E29="","",IFERROR(INDEX(Catégories!$C$5:$C$60,MATCH(E29,Catégories!$A$5:$A$60,0)),"?")) -> Déductible | J29: =IF(E29="","",IFERROR(INDEX(Catégories!$D$5:$D$60,MATCH(E29,Catégories!$A$5:$A$60,0)),"?")) -> Frais de gestion | K29: =IF(H29="Recette",G29,IF(H29="Dépense",-G29,0)) -> -2.74 | L29: =IF(E29="",0,G29*IFERROR(INDEX(Catégories!$E$5:$E$60,MATCH(E29,Catégories!$A$5:$A$60,0)),0)) -> -2.74 | M29: Bien/04_Agence/2024-05_2026-11_AGENCE_Grand-livre-proprietaire.pdf | N29: Grand livre agence
A30: 45448 | B30: =IF(A30="","",YEAR(A30)) -> 2024 | C30: APPART-01 | D30: Agence | E30: Honoraires sur travaux | F30: TVA HONORAIRES GESTION TRAVAUX 3% TTC (ARTISAN C) | G30: 0.55 | H30: =IF(E30="","",IFERROR(INDEX(Catégories!$B$5:$B$60,MATCH(E30,Catégories!$A$5:$A$60,0)),"?")) -> Dépense | I30: =IF(E30="","",IFERROR(INDEX(Catégories!$C$5:$C$60,MATCH(E30,Catégories!$A$5:$A$60,0)),"?")) -> Déductible | J30: =IF(E30="","",IFERROR(INDEX(Catégories!$D$5:$D$60,MATCH(E30,Catégories!$A$5:$A$60,0)),"?")) -> Frais de gestion | K30: =IF(H30="Recette",G30,IF(H30="Dépense",-G30,0)) -> -0.55 | L30: =IF(E30="",0,G30*IFERROR(INDEX(Catégories!$E$5:$E$60,MATCH(E30,Catégories!$A$5:$A$60,0)),0)) -> -0.55 | M30: Bien/04_Agence/2024-05_2026-11_AGENCE_Grand-livre-proprietaire.pdf | N30: Grand livre agence
... A33: 45449 | B33: =IF(A33="","",YEAR(A33)) -> 2024 | C33: APPART-01 | D33: Agence | E33: Transfert sortant | F33: Virement de l'agence au propriétaire | G33: 480.09 | H33: =IF(E33="","",IFERROR(INDEX(Catégories!$B$5:$B$60,MATCH(E33,Catégories!$A$5:$A$60,0)),"?")) -> Transfert | I33: =IF(E33="","",IFERROR(INDEX(Catégories!$C$5:$C$60,MATCH(E33,Catégories!$A$5:$A$60,0)),"?")) -> Non fiscal | J33: =IF(E33="","",IFERROR(INDEX(Catégories!$D$5:$D$60,MATCH(E33,Catégories!$A$5:$A$60,0)),"?")) -> Mouvements internes | K33: =IF(H33="Recette",G33,IF(H33="Dépense",-G33,0)) -> 0 | L33: =IF(E33="",0,G33*IFERROR(INDEX(Catégories!$E$5:$E$60,MATCH(E33,Catégories!$A$5:$A$60,0)),0)) -> -480.09 | M33: Bien/04_Agence/2024-05_2026-11_AGENCE_Grand-livre-proprietaire.pdf | N33: Grand livre agence
A34: 45450 | B34: =IF(A34="","",YEAR(A34)) -> 2024 | C34: APPART-01 | D34: Banque | E34: Équipement / mobilier (à amortir) | F34: VIR SEPA DEVIS FRIGO NEUF | G34: 1076.01 | H34: =IF(E34="","",IFERROR(INDEX(Catégories!$B$5:$B$60,MATCH(E34,Catégories!$A$5:$A$60,0)),"?")) -> Dépense | I34: =IF(E34="","",IFERROR(INDEX(Catégories!$C$5:$C$60,MATCH(E34,Catégories!$A$5:$A$60,0)),"?")) -> À amortir | J34: =IF(E34="","",IFERROR(INDEX(Catégories!$D$5:$D$60,MATCH(E34,Catégories!$A$5:$A$60,0)),"?")) -> Investissements | K34: =IF(H34="Recette",G34,IF(H34="Dépense",-G34,0)) -> -1076.01 | L34: =IF(E34="",0,G34*IFERROR(INDEX(Catégories!$E$5:$E$60,MATCH(E34,Catégories!$A$5:$A$60,0)),0)) -> -1076.01 | M34: Banque/Banque_Exempleville_Revenus-Depenses_2024-2026.xlsx | N34: Relevé BANQUE | O34: Réfrigérateur, immobilisé par le comptable
A35: 45450 | B35: =IF(A35="","",YEAR(A35)) -> 2024 | C35: APPART-01 | D35: Banque | E35: Petit équipement | F35: VIR SEPA EXEMPLEVILLE - REPARATION FR | G35: 88.35 | H35: =IF(E35="","",IFERROR(INDEX(Catégories!$B$5:$B$60,MATCH(E35,Catégories!$A$5:$A$60,0)),"?")) -> Dépense | I35: =IF(E35="","",IFERROR(INDEX(Catégories!$C$5:$C$60,MATCH(E35,Catégories!$A$5:$A$60,0)),"?")) -> Déductible | J35: =IF(E35="","",IFERROR(INDEX(Catégories!$D$5:$D$60,MATCH(E35,Catégories!$A$5:$A$60,0)),"?")) -> Entretien et petit équipement | K35: =IF(H35="Recette",G35,IF(H35="Dépense",-G35,0)) -> -88.35 | L35: =IF(E35="",0,G35*IFERROR(INDEX(Catégories!$E$5:$E$60,MATCH(E35,Catégories!$A$5:$A$60,0)),0)) -> -88.35 | M35: Banque/Banque_Exempleville_Revenus-Depenses_2024-2026.xlsx | N35: Relevé BANQUE | O35: Passé en petit équipement par le comptable
A36: 45475 | B36: =IF(A36="","",YEAR(A36)) -> 2024 | C36: APPART-01 | D36: Agence | E36: Loyer hors charges | F36: LOYER PRINCIPAL (01/07/2024 - 31/07/2024) | G36: 1032.3 | H36: =IF(E36="","",IFERROR(INDEX(Catégories!$B$5:$B$60,MATCH(E36,Catégories!$A$5:$A$60,0)),"?")) -> Recette | I36: =IF(E36="","",IFERROR(INDEX(Catégories!$C$5:$C$60,MATCH(E36,Catégories!$A$5:$A$60,0)),"?")) -> Imposable | J36: =IF(E36="","",IFERROR(INDEX(Catégories!$D$5:$D$60,MATCH(E36,Catégories!$A$5:$A$60,0)),"?")) -> Loyers | K36: =IF(H36="Recette",G36,IF(H36="Dépense",-G36,0)) -> 1032.3 | L36: =IF(E36="",0,G36*IFERROR(INDEX(Catégories!$E$5:$E$60,MATCH(E36,Catégories!$A$5:$A$60,0)),0)) -> 1032.3 | M36: Bien/04_Agence/2024-05_2026-11_AGENCE_Grand-livre-proprietaire.pdf | N36: Grand livre agence
A37: 45475 | B37: =IF(A37="","",YEAR(A37)) -> 2024 | C37: APPART-01 | D37: Agence | E37: Honoraires de gestion | F37: HONORAIRES GESTION LOYER PRINCIPAL 6.00% | G37: 61.94 | H37: =IF(E37="","",IFERROR(INDEX(Catégories!$B$5:$B$60,MATCH(E37,Catégories!$A$5:$A$60,0)),"?")) -> Dépense | I37: =IF(E37="","",IFERROR(INDEX(Catégories!$C$5:$C$60,MATCH(E37,Catégories!$A$5:$A$60,0)),"?")) -> Déductible | J37: =IF(E37="","",IFERROR(INDEX(Catégories!$D$5:$D$60,MATCH(E37,Catégories!$A$5:$A$60,0)),"?")) -> Frais de gestion | K37: =IF(H37="Recette",G37,IF(H37="Dépense",-G37,0)) -> -61.94 | L37: =IF(E37="",0,G37*IFERROR(INDEX(Catégories!$E$5:$E$60,MATCH(E37,Catégories!$A$5:$A$60,0)),0)) -> -61.94 | M37: Bien/04_Agence/2024-05_2026-11_AGENCE_Grand-livre-proprietaire.pdf | N37: Grand livre agence
A38: 45475 | B38: =IF(A38="","",YEAR(A38)) -> 2024 | C38: APPART-01 | D38: Agence | E38: Honoraires de gestion | F38: TVA HONORAIRES GESTION LOYER PRINCIPAL | G38: 12.39 | H38: =IF(E38="","",IFERROR(INDEX(Catégories!$B$5:$B$60,MATCH(E38,Catégories!$A$5:$A$60,0)),"?")) -> Dépense | I38: =IF(E38="","",IFERROR(INDEX(Catégories!$C$5:$C$60,MATCH(E38,Catégories!$A$5:$A$60,0)),"?")) -> Déductible | J38: =IF(E38="","",IFERROR(INDEX(Catégories!$D$5:$D$60,MATCH(E38,Catégories!$A$5:$A$60,0)),"?")) -> Frais de gestion | K38: =IF(H38="Recette",G38,IF(H38="Dépense",-G38,0)) -> -12.39 | L38: =IF(E38="",0,G38*IFERROR(INDEX(Catégories!$E$5:$E$60,MATCH(E38,Catégories!$A$5:$A$60,0)),0)) -> -12.39 | M38: Bien/04_Agence/2024-05_2026-11_AGENCE_Grand-livre-proprietaire.pdf | N38: Grand livre agence
A39: 45475 | B39: =IF(A39="","",YEAR(A39)) -> 2024 | C39: APPART-01 | D39: Agence | E39: Provisions sur charges | F39: PROVISIONS CHARGES (01/07/2024 - 31/07/2024) | G39: 83.7 | H39: =IF(E39="","",IFERROR(INDEX(Catégories!$B$5:$B$60,MATCH(E39,Catégories!$A$5:$A$60,0)),"?")) -> Recette | I39: =IF(E39="","",IFERROR(INDEX(Catégories!$C$5:$C$60,MATCH(E39,Catégories!$A$5:$A$60,0)),"?")) -> Imposable | J39: =IF(E39="","",IFERROR(INDEX(Catégories!$D$5:$D$60,MATCH(E39,Catégories!$A$5:$A$60,0)),"?")) -> Charges refacturées | K39: =IF(H39="Recette",G39,IF(H39="Dépense",-G39,0)) -> 83.7 | L39: =IF(E39="",0,G39*IFERROR(INDEX(Catégories!$E$5:$E$60,MATCH(E39,Catégories!$A$5:$A$60,0)),0)) -> 83.7 | M39: Bien/04_Agence/2024-05_2026-11_AGENCE_Grand-livre-proprietaire.pdf | N39: Grand livre agence
A40: 45475 | B40: =IF(A40="","",YEAR(A40)) -> 2024 | C40: APPART-01 | D40: Agence | E40: Honoraires de gestion | F40: HONORAIRES GESTION PROVISIONS CHARGES 6.00% | G40: 5.02 | H40: =IF(E40="","",IFERROR(INDEX(Catégories!$B$5:$B$60,MATCH(E40,Catégories!$A$5:$A$60,0)),"?")) -> Dépense | I40: =IF(E40="","",IFERROR(INDEX(Catégories!$C$5:$C$60,MATCH(E40,Catégories!$A$5:$A$60,0)),"?")) -> Déductible | J40: =IF(E40="","",IFERROR(INDEX(Catégories!$D$5:$D$60,MATCH(E40,Catégories!$A$5:$A$60,0)),"?")) -> Frais de gestion | K40: =IF(H40="Recette",G40,IF(H40="Dépense",-G40,0)) -> -5.02 | L40: =IF(E40="",0,G40*IFERROR(INDEX(Catégories!$E$5:$E$60,MATCH(E40,Catégories!$A$5:$A$60,0)),0)) -> -5.02 | M40: Bien/04_Agence/2024-05_2026-11_AGENCE_Grand-livre-proprietaire.pdf | N40: Grand livre agence
A41: 45475 | B41: =IF(A41="","",YEAR(A41)) -> 2024 | C41: APPART-01 | D41: Agence | E41: Honoraires de gestion | F41: TVA HONORAIRES GESTION PROVISIONS CHARGES | G41: 1 | H41: =IF(E41="","",IFERROR(INDEX(Catégories!$B$5:$B$60,MATCH(E41,Catégories!$A$5:$A$60,0)),"?")) -> Dépense | I41: =IF(E41="","",IFERROR(INDEX(Catégories!$C$5:$C$60,MATCH(E41,Catégories!$A$5:$A$60,0)),"?")) -> Déductible | J41: =IF(E41="","",IFERROR(INDEX(Catégories!$D$5:$D$60,MATCH(E41,Catégories!$A$5:$A$60,0)),"?")) -> Frais de gestion | K41: =IF(H41="Recette",G41,IF(H41="Dépense",-G41,0)) -> -1 | L41: =IF(E41="",0,G41*IFERROR(INDEX(Catégories!$E$5:$E$60,MATCH(E41,Catégories!$A$5:$A$60,0)),0)) -> -1 | M41: Bien/04_Agence/2024-05_2026-11_AGENCE_Grand-livre-proprietaire.pdf | N41: Grand livre agence
A42: 45475 | B42: =IF(A42="","",YEAR(A42)) -> 2024 | C42: APPART-01 | D42: Agence | E42: Transfert sortant | F42: Virement de l'agence au propriétaire | G42: 1035.65 | H42: =IF(E42="","",IFERROR(INDEX(Catégories!$B$5:$B$60,MATCH(E42,Catégories!$A$5:$A$60,0)),"?")) -> Transfert | I42: =IF(E42="","",IFERROR(INDEX(Catégories!$C$5:$C$60,MATCH(E42,Catégories!$A$5:$A$60,0)),"?")) -> Non fiscal | J42: =IF(E42="","",IFERROR(INDEX(Catégories!$D$5:$D$60,MATCH(E42,Catégories!$A$5:$A$60,0)),"?")) -> Mouvements internes | K42: =IF(H42="Recette",G42,IF(H42="Dépense",-G42,0)) -> 0 | L42: =IF(E42="",0,G42*IFERROR(INDEX(Catégories!$E$5:$E$60,MATCH(E42,Catégories!$A$5:$A$60,0)),0)) -> -1035.65 | M42: Bien/04_Agence/2024-05_2026-11_AGENCE_Grand-livre-proprietaire.pdf | N42: Grand livre agence
A43: 45506 | B43: =IF(A43="","",YEAR(A43)) -> 2024 | C43: APPART-01 | D43: Agence | E43: Loyer hors charges | F43: LOYER PRINCIPAL (01/08/2024 - 31/08/2024) | G43: 1032.3 | H43: =IF(E43="","",IFERROR(INDEX(Catégories!$B$5:$B$60,MATCH(E43,Catégories!$A$5:$A$60,0)),"?")) -> Recette | I43: =IF(E43="","",IFERROR(INDEX(Catégories!$C$5:$C$60,MATCH(E43,Catégories!$A$5:$A$60,0)),"?")) -> Imposable | J43: =IF(E43="","",IFERROR(INDEX(Catégories!$D$5:$D$60,MATCH(E43,Catégories!$A$5:$A$60,0)),"?")) -> Loyers | K43: =IF(H43="Recette",G43,IF(H43="Dépense",-G43,0)) -> 1032.3 | L43: =IF(E43="",0,G43*IFERROR(INDEX(Catégories!$E$5:$E$60,MATCH(E43,Catégories!$A$5:$A$60,0)),0)) -> 1032.3 | M43: Bien/04_Agence/2024-05_2026-11_AGENCE_Grand-livre-proprietaire.pdf | N43: Grand livre agence
...

Sheet Biens
A1: Biens
A2: Une ligne par bien. Les cellules jaunes sont à renseigner. L'identifiant (colonne A) relie le bien au journal, aux prêts et aux amortissements.
A4: Identifiant | B4: Nom | C4: Adresse | D4: Code postal | E4: Ville | F4: Type de location | G4: Régime fiscal | H4: Date d'acquisition | I4: Prix d'achat (net vendeur) | J4: dont mobilier | K4: Frais d'agence (achat) | L4: Frais de notaire et de garantie | M4: Coût total d'acquisition | N4: Apport personnel | O4: Date de mise en location | P4: Valeur estimée actuelle | Q4: Surface (m²) | R4: Gestionnaire | S4: Syndic | T4: Loyer hors charges actuel | U4: Provision sur charges | V4: Dépôt de garantie
A5: APPART-01 | B5: Appartement exemple | C5: 1 rue de l'Exemple | E5: Exempleville | F5: Meublée | G5: LMNP réel | H5: 43049 | I5: 239010 | J5: 7440 | K5: 9300 | L5: 19848.99 | M5: =IF(A5="","",I5+K5+L5) -> 268158.99 | N5: 97968.99 | O5: 45430 | P5: 283650 | Q5: 40.03 | R5: Agence exemple (6 % HT) | S5: Syndic exemple | T5: 1054.89 | U5: 83.7 | V5: 2064.6
M6: =IF(A6="","",I6+K6+L6)
M7: =IF(A7="","",I7+K7+L7)
M8: =IF(A8="","",I8+K8+L8)
M9: =IF(A9="","",I9+K9+L9)
M10: =IF(A10="","",I10+K10+L10)
M11: =IF(A11="","",I11+K11+L11)
M12: =IF(A12="","",I12+K12+L12)
M13: =IF(A13="","",I13+K13+L13)
M14: =IF(A14="","",I14+K14+L14)
M15: =IF(A15="","",I15+K15+L15)
M16: =IF(A16="","",I16+K16+L16)
M17: =IF(A17="","",I17+K17+L17)
... M30: =IF(A30="","",I30+K30+L30)

Sheet Catégories
A1: Catégories
A2: Chaque catégorie détermine le sens du mouvement, son traitement fiscal (LMNP réel) et son groupe dans la synthèse. Les intérêts et le capital du prêt ne passent pas par le journal : ils viennent de l'onglet Échéancier.
A4: Catégorie | B4: Sens | C4: Traitement fiscal (LMNP réel) | D4: Groupe (synthèse) | E4: Signe trésorerie | F4: Description
A5: Loyer hors charges | B5: Recette | C5: Imposable | D5: Loyers | E5: 1 | F5: Loyer brut, avant honoraires (une remise de loyer se saisit en montant négatif)
A6: Provisions sur charges | B6: Recette | C6: Imposable | D6: Charges refacturées | E6: 1 | F6: Provisions mensuelles payées par le locataire
A7: Régularisation de charges locataire | B7: Recette | C7: Imposable | D7: Charges refacturées | E7: 1 | F7: Solde annuel réclamé (ou rendu, en négatif) au locataire
A8: Taxe ordures ménagères refacturée | B8: Recette | C8: Imposable | D8: Charges refacturées | E8: 1 | F8: TEOM refacturée au locataire
A9: Autres recettes | B9: Recette | C9: Imposable | D9: Autres recettes | E9: 1 | F9: Indemnités, refacturations diverses
A10: Honoraires de gestion | B10: Dépense | C10: Déductible | D10: Frais de gestion | E10: -1 | F10: Honoraires de l'agence, TVA comprise
A11: Honoraires de mise en location | B11: Dépense | C11: Déductible | D11: Frais de gestion | E11: -1 | F11: Recherche de locataire, état des lieux
A12: Honoraires sur travaux | B12: Dépense | C12: Déductible | D12: Frais de gestion | E12: -1 | F12: Commission de l'agence sur les travaux
A13: Honoraires comptable | B13: Dépense | C13: Déductible | D13: Frais de gestion | E13: -1 | F13: Expert-comptable, centre de gestion
A14: Charges de copropriété | B14: Dépense | C14: Déductible | D14: Copropriété | E14: -1 | F14: Appels de fonds payés au syndic (charges, travaux, fonds de travaux)
A15: Assurance PNO | B15: Dépense | C15: Déductible | D15: Assurances | E15: -1 | F15: Assurance propriétaire non occupant, loyers impayés
A16: Taxe foncière | B16: Dépense | C16: Déductible | D16: Impôts et taxes | E16: -1 | F16: Taxe foncière (TEOM incluse)
... A28: Dépôt de garantie restitué | B28: Neutre | C28: Non fiscal | D28: Dépôt de garantie | E28: -1 | F28: Restitution au locataire

Sheet Prêts
A1: Prêts
